Workbook

Sheet Summary
A1: A faster ordering for Find the chord: current plan vs. proposals
A2: Same mechanics as today (keys and chord groups introduced one at a time; a new chord group resets the keys to the first two, a new key resets the chords to the first group). What changes is the ORDER of keys, the ORDER of chord groups, and when each is introduced. Plan A reorders only. Plan B also adds two groups of common chromatic chords. All figures are rough estimates on the same model as the chunk-coverage sheet; nothing in the app has been changed.
A4: Levels needed to reach this share of songs | B4: Pop: current | C4: Pop: Plan A (reordered) | D4: Pop: Plan B (+ borrowed chords) | E4: Jazz: current | F4: Jazz: Plan A (reordered) | G4: Jazz: Plan B (+ chromatic chords)
A5: 0.05 | B5: =IF(MAX(Curves!B$2:B$211)<$A5,"never",COUNTIF(Curves!B$2:B$211,"<"&$A5)+1) -> 5 | C5: =IF(MAX(Curves!C$2:C$211)<$A5,"never",COUNTIF(Curves!C$2:C$211,"<"&$A5)+1) -> 3 | D5: =IF(MAX(Curves!D$2:D$211)<$A5,"never",COUNTIF(Curves!D$2:D$211,"<"&$A5)+1) -> 3 | E5: =IF(MAX(Curves!E$2:E$211)<$A5,"never",COUNTIF(Curves!E$2:E$211,"<"&$A5)+1) -> 51 | F5: =IF(MAX(Curves!F$2:F$211)<$A5,"never",COUNTIF(Curves!F$2:F$211,"<"&$A5)+1) -> 13 | G5: =IF(MAX(Curves!G$2:G$211)<$A5,"never",COUNTIF(Curves!G$2:G$211,"<"&$A5)+1) -> 5
A6: 0.1 | B6: =IF(MAX(Curves!B$2:B$211)<$A6,"never",COUNTIF(Curves!B$2:B$211,"<"&$A6)+1) -> 7 | C6: =IF(MAX(Curves!C$2:C$211)<$A6,"never",COUNTIF(Curves!C$2:C$211,"<"&$A6)+1) -> 5 | D6: =IF(MAX(Curves!D$2:D$211)<$A6,"never",COUNTIF(Curves!D$2:D$211,"<"&$A6)+1) -> 4 | E6: =IF(MAX(Curves!E$2:E$211)<$A6,"never",COUNTIF(Curves!E$2:E$211,"<"&$A6)+1) -> 122 | F6: =IF(MAX(Curves!F$2:F$211)<$A6,"never",COUNTIF(Curves!F$2:F$211,"<"&$A6)+1) -> 78 | G6: =IF(MAX(Curves!G$2:G$211)<$A6,"never",COUNTIF(Curves!G$2:G$211,"<"&$A6)+1) -> 6
A7: 0.2 | B7: =IF(MAX(Curves!B$2:B$211)<$A7,"never",COUNTIF(Curves!B$2:B$211,"<"&$A7)+1) -> 11 | C7: =IF(MAX(Curves!C$2:C$211)<$A7,"never",COUNTIF(Curves!C$2:C$211,"<"&$A7)+1) -> 11 | D7: =IF(MAX(Curves!D$2:D$211)<$A7,"never",COUNTIF(Curves!D$2:D$211,"<"&$A7)+1) -> 10 | E7: =IF(MAX(Curves!E$2:E$211)<$A7,"never",COUNTIF(Curves!E$2:E$211,"<"&$A7)+1) -> never | F7: =IF(MAX(Curves!F$2:F$211)<$A7,"never",COUNTIF(Curves!F$2:F$211,"<"&$A7)+1) -> never | G7: =IF(MAX(Curves!G$2:G$211)<$A7,"never",COUNTIF(Curves!G$2:G$211,"<"&$A7)+1) -> 16
A8: 0.3 | B8: =IF(MAX(Curves!B$2:B$211)<$A8,"never",COUNTIF(Curves!B$2:B$211,"<"&$A8)+1) -> 25 | C8: =IF(MAX(Curves!C$2:C$211)<$A8,"never",COUNTIF(Curves!C$2:C$211,"<"&$A8)+1) -> 19 | D8: =IF(MAX(Curves!D$2:D$211)<$A8,"never",COUNTIF(Curves!D$2:D$211,"<"&$A8)+1) -> 16 | E8: =IF(MAX(Curves!E$2:E$211)<$A8,"never",COUNTIF(Curves!E$2:E$211,"<"&$A8)+1) -> never | F8: =IF(MAX(Curves!F$2:F$211)<$A8,"never",COUNTIF(Curves!F$2:F$211,"<"&$A8)+1) -> never | G8: =IF(MAX(Curves!G$2:G$211)<$A8,"never",COUNTIF(Curves!G$2:G$211,"<"&$A8)+1) -> 41
A9: 0.4 | B9: =IF(MAX(Curves!B$2:B$211)<$A9,"never",COUNTIF(Curves!B$2:B$211,"<"&$A9)+1) -> 37 | C9: =IF(MAX(Curves!C$2:C$211)<$A9,"never",COUNTIF(Curves!C$2:C$211,"<"&$A9)+1) -> 31 | D9: =IF(MAX(Curves!D$2:D$211)<$A9,"never",COUNTIF(Curves!D$2:D$211,"<"&$A9)+1) -> 21 | E9: =IF(MAX(Curves!E$2:E$211)<$A9,"never",COUNTIF(Curves!E$2:E$211,"<"&$A9)+1) -> never | F9: =IF(MAX(Curves!F$2:F$211)<$A9,"never",COUNTIF(Curves!F$2:F$211,"<"&$A9)+1) -> never | G9: =IF(MAX(Curves!G$2:G$211)<$A9,"never",COUNTIF(Curves!G$2:G$211,"<"&$A9)+1) -> 92
A10: 0.5 | B10: =IF(MAX(Curves!B$2:B$211)<$A10,"never",COUNTIF(Curves!B$2:B$211,"<"&$A10)+1) -> 89 | C10: =IF(MAX(Curves!C$2:C$211)<$A10,"never",COUNTIF(Curves!C$2:C$211,"<"&$A10)+1) -> 78 | D10: =IF(MAX(Curves!D$2:D$211)<$A10,"never",COUNTIF(Curves!D$2:D$211,"<"&$A10)+1) -> 31 | E10: =IF(MAX(Curves!E$2:E$211)<$A10,"never",COUNTIF(Curves!E$2:E$211,"<"&$A10)+1) -> never | F10: =IF(MAX(Curves!F$2:F$211)<$A10,"never",COUNTIF(Curves!F$2:F$211,"<"&$A10)+1) -> never | G10: =IF(MAX(Curves!G$2:G$211)<$A10,"never",COUNTIF(Curves!G$2:G$211,"<"&$A10)+1) -> never
A11: 0.6 | B11: =IF(MAX(Curves!B$2:B$211)<$A11,"never",COUNTIF(Curves!B$2:B$211,"<"&$A11)+1) -> never | C11: =IF(MAX(Curves!C$2:C$211)<$A11,"never",COUNTIF(Curves!C$2:C$211,"<"&$A11)+1) -> never | D11: =IF(MAX(Curves!D$2:D$211)<$A11,"never",COUNTIF(Curves!D$2:D$211,"<"&$A11)+1) -> 41 | E11: =IF(MAX(Curves!E$2:E$211)<$A11,"never",COUNTIF(Curves!E$2:E$211,"<"&$A11)+1) -> never | F11: =IF(MAX(Curves!F$2:F$211)<$A11,"never",COUNTIF(Curves!F$2:F$211,"<"&$A11)+1) -> never | G11: =IF(MAX(Curves!G$2:G$211)<$A11,"never",COUNTIF(Curves!G$2:G$211,"<"&$A11)+1) -> never
A12: Songs playable at level 30 | B12: =Curves!B31 -> 0.33892421 | C12: =Curves!C31 -> 0.39144464 | D12: =Curves!D31 -> 0.49349474 | E12: =Curves!E31 -> 0.043033436 | F12: =Curves!F31 -> 0.068650045 | G12: =Curves!G31 -> 0.25667622
A13: Songs playable at level 60 | B13: =Curves!B61 -> 0.46227894 | C13: =Curves!C61 -> 0.46498232 | D13: =Curves!D61 -> 0.7536315 | E13: =Curves!E61 -> 0.08265395 | F13: =Curves!F61 -> 0.091397317 | G13: =Curves!G61 -> 0.34441175
A14: Songs playable at the top level (ceiling) | B14: =MAX(Curves!B2:B211) -> 0.54289564 | C14: =MAX(Curves!C2:C211) -> 0.54289564 | D14: =MAX(Curves!D2:D211) -> 0.9272165 | E14: =MAX(Curves!E2:E211) -> 0.12174074 | F14: =MAX(Curves!F2:F211) -> 0.12174074 | G14: =MAX(Curves!G2:G211) -> 0.47721445
A16: What drives the gain
A17: 1. Introduce vi and ii after only two keys, not five. Chord coverage is the bottleneck (a song needs ALL its chords), and a new chord group is cheapest while few keys are known, because the keys only climb back from the C and the second key.
A18: 2. Order keys by how much music is in them, per genre: Pop C G D A F E ...; Jazz C F B♭ E♭ A♭ G ... Today Jazz meets D and A (rare in jazz) before B♭ and E♭, and Pop meets D♭ before E.
A19: 3. Order chord groups by how much music they cover, per genre. Pop: I IV V V7, vi ii, iii vii°, then sus4/add9/sus2 before sevenths (Pop uses few sevenths). Jazz: sevenths (group 3) come right after the first group, then iii7/vii°7.
A20: 4. Plan B: the biggest lever is not order but ceiling. The app only asks diatonic chords, so Pop is capped near 54% of songs and Jazz near 12%. Adding two small groups of the most common non-diatonic chords lifts those ceilings to about 93% and 48%, and does so early.

Sheet Curves
A1: Level | B1: Pop: current | C1: Pop: reordered | D1: Pop: reordered + borrowed chords | E1: Jazz: current | F1: Jazz: reordered | G1: Jazz: reordered + secondary dominants etc.
A2: 1 | B2: 0.012556135 | C2: 0.012556135 | D2: 0.012556135 | E2: 1.0443068e-05 | F2: 1.0443068e-05 | G2: 1.0443068e-05
A3: 2 | B3: 0.023252102 | C3: 0.024182186 | D3: 0.024182186 | E3: 1.4545702e-05 | F3: 2.4615804e-05 | G3: 2.4615804e-05
A4: 3 | B4: 0.034878154 | C4: 0.092036949 | D4: 0.092036949 | E4: 2.051317e-05 | F4: 0.013293093 | G4: 0.013293093
A5: 4 | B5: 0.043713952 | C5: 0.092036949 | D5: 0.13156288 | E5: 2.3123937e-05 | F5: 0.023880815 | G5: 0.034263702
A6: 5 | B6: 0.052084709 | C6: 0.1327456 | D6: 0.16024335 | E6: 3.5804806e-05 | F6: 0.023880815 | G6: 0.056705932
A7: 6 | B7: 0.088497066 | C7: 0.1327456 | D7: 0.19892811 | E7: 3.5804806e-05 | F7: 0.023880815 | G7: 0.10457179
A8: 7 | B8: 0.1327456 | C8: 0.16637448 | D8: 0.19892811 | E8: 3.5804806e-05 | F8: 0.036183053 | G8: 0.10457179
A9: 8 | B9: 0.16637448 | C9: 0.16637448 | D9: 0.19892811 | E9: 3.5804806e-05 | F9: 0.036183053 | G9: 0.10457179
A10: 9 | B10: 0.19823343 | C10: 0.19823343 | D10: 0.19892811 | E10: 4.7648465e-05 | F10: 0.036183053 | G10: 0.10457179
A11: 10 | B11: 0.19823343 | C11: 0.19823343 | D11: 0.23112022 | E11: 4.7648465e-05 | F11: 0.046314308 | G11: 0.10457179
A12: 11 | B12: 0.21770278 | C12: 0.22832243 | D12: 0.28691555 | E12: 5.2115509e-05 | F12: 0.046314308 | G12: 0.15844211
A13: 12 | B13: 0.21770278 | C13: 0.22832243 | D13: 0.28691555 | E13: 5.3334242e-05 | F13: 0.046314308 | G13: 0.15844211
... A145: 144 | B145: 0.54289564 | C145: 0.54289564 | D145: 0.91784129 | E145: 0.117649 | F145: 0.117649 | G145: 0.45040195
A146: 145 | D146: 0.91784129 | E146: 0.117649 | F146: 0.117649 | G146: 0.45040195
A147: 146 | D147: 0.91784129 | E147: 0.117649 | F147: 0.117649 | G147: 0.45040195
A148: 147 | D148: 0.91784129 | E148: 0.117649 | F148: 0.117649 | G148: 0.45040195
A149: 148 | D149: 0.91784129 | E149: 0.117649 | F149: 0.117649 | G149: 0.45040195
A150: 149 | D150: 0.91784129 | E150: 0.117649 | F150: 0.117649 | G150: 0.45040195
A151: 150 | D151: 0.91784129 | E151: 0.117649 | F151: 0.117649 | G151: 0.45120104
A152: 151 | D152: 0.91784129 | E152: 0.117649 | F152: 0.117649 | G152: 0.45740302
A153: 152 | D153: 0.91784129 | E153: 0.117649 | F153: 0.117649 | G153: 0.45740302
A154: 153 | D154: 0.91784129 | E154: 0.117649 | F154: 0.117649 | G154: 0.45740302
A155: 154 | D155: 0.91784129 | E155: 0.117649 | F155: 0.117649 | G155: 0.45740302
A156: 155 | D156: 0.92251937 | E156: 0.11866103 | F156: 0.11866103 | G156: 0.45740302
A157: 156 | D157: 0.92251937 | E157: 0.11866103 | F157: 0.11866103 | G157: 0.45740302
... A167: 166 | D167: 0.9272165 | E167: 0.1196803 | F167: 0.1196803 | G167: 0.46440409
A168: 167 | E168: 0.1196803 | F168: 0.1196803 | G168: 0.46440409
A169: 168 | E169: 0.1196803 | F169: 0.1196803 | G169: 0.46440409
A170: 169 | E170: 0.1196803 | F170: 0.1196803 | G170: 0.46440409
A171: 170 | E171: 0.1196803 | F171: 0.1196803 | G171: 0.46440409
A172: 171 | E172: 0.1196803 | F172: 0.1196803 | G172: 0.46440409
A173: 172 | E173: 0.1196803 | F173: 0.1196803 | G173: 0.46440409
A174: 173 | E174: 0.1196803 | F174: 0.1196803 | G174: 0.46440409
A175: 174 | E175: 0.1196803 | F175: 0.1196803 | G175: 0.46440409
A176: 175 | E176: 0.1196803 | F176: 0.1196803 | G176: 0.46440409
A177: 176 | E177: 0.1196803 | F177: 0.1196803 | G177: 0.46440409
A178: 177 | E178: 0.12070686 | F178: 0.12070686 | G178: 0.46757949
A179: 178 | E179: 0.12070686 | F179: 0.12070686 | G179: 0.46757949
... A189: 188 | E189: 0.12174074 | F189: 0.12174074 | G189: 0.47077296
...

Sheet Pop Plan A
A1: Pop Plan A — key order: C, G, D, A, F, E, B♭, E♭, A♭, D♭, B, F♯
A3: Chunk | B3: Chords added (group) | C3: Original group # | D3: Levels | E3: Keys at chunk end | F3: Newly in this chunk: keys | G3: Chord use added | H3: Chord use, cumulative | I3: Key coverage, cumulative | J3: Songs playable, cumulative | K3: Songs added by this chunk
A4: 1 | B4: I, IV, V, V7 | C4: 1 | D4: 1–2 | E4: 2 | F4: C, G | G4: 0.62 | H4: 0.62 | I4: 0.26395939 | J4: 0.024182186 | K4: 0.024182186
A5: 2 | B5: vi, ii | C5: 2 | D5: 3–11 | E5: 6 | F5: D, A, F, E | G5: 0.19 | H5: 0.81 | I5: 0.65482234 | J5: 0.22832243 | K5: 0.20414024
A6: 3 | B6: iii, vii° | C6: 4 | D6: 12–34 | E6: 12 | F6: B♭, E♭, A♭, D♭, B, F♯ | G6: 0.035 | H6: 0.845 | I6: 1 | J6: 0.43080779 | K6: 0.20248536
A7: 4 | B7: sus4: I, V, IV | C7: 6 | D7: 35–45 | E7: 12 | F7: – | G7: 0.007 | H7: 0.852 | I7: 1 | J7: 0.44895 | K7: 0.018142211
A8: 5 | B8: add9: I, V, IV | C8: 10 | D8: 46–56 | E8: 12 | F8: – | G8: 0.006 | H8: 0.858 | I8: 1 | J8: 0.46498232 | K8: 0.016032321
A9: 6 | B9: sus2: I, V, IV | C9: 8 | D9: 57–67 | E9: 12 | F9: – | G9: 0.005 | H9: 0.863 | I9: 1 | J9: 0.47868959 | K9: 0.013707266
A10: 7 | B10: I7, IV7, ii7, vi7 | C10: 3 | D10: 68–78 | E10: 12 | F10: – | G10: 0.011 | H10: 0.874 | I10: 1 | J10: 0.50998472 | K10: 0.031295134
A11: 8 | B11: 9th: I, V, IV | C11: 12 | D11: 79–89 | E11: 12 | F11: – | G11: 0.003 | H11: 0.877 | I11: 1 | J11: 0.51879761 | K11: 0.0088128912
A12: 9 | B12: sus4: vi, ii, iii, vii° | C12: 7 | D12: 90–100 | E12: 12 | F12: – | G12: 0.002 | H12: 0.879 | I12: 1 | J12: 0.52474025 | K12: 0.0059426368
A13: 10 | B13: sus2: vi, ii, iii, vii° | C13: 9 | D13: 101–111 | E13: 12 | F13: – | G13: 0.002 | H13: 0.881 | I13: 1 | J13: 0.53073722 | K13: 0.0059969691
A14: 11 | B14: add9: vi, ii, iii, vii° | C14: 11 | D14: 112–122 | E14: 12 | F14: – | G14: 0.002 | H14: 0.883 | I14: 1 | J14: 0.53678889 | K14: 0.0060516731
A15: 12 | B15: iii7, vii°7 | C15: 5 | D15: 123–133 | E15: 12 | F15: – | G15: 0.001 | H15: 0.884 | I15: 1 | J15: 0.53983536 | K15: 0.0030464671
A16: 13 | B16: 9th: vi, ii, iii, vii° | C16: 13 | D16: 134–144 | E16: 12 | F16: – | G16: 0.001 | H16: 0.885 | I16: 1 | J16: 0.54289564 | K16: 0.0030602833

Sheet Jazz Plan A
A1: Jazz Plan A — key order: C, B♭, F, E♭, A♭, G, D, D♭, A, E, B, F♯
A3: Chunk | B3: Chords added (group) | C3: Original group # | D3: Levels | E3: Keys at chunk end | F3: Newly in this chunk: keys | G3: Chord use added | H3: Chord use, cumulative | I3: Key coverage, cumulative | J3: Songs playable, cumulative | K3: Songs added by this chunk
A4: 1 | B4: I, IV, V, V7 | C4: 1 | D4: 1–2 | E4: 2 | F4: C, B♭ | G4: 0.205 | H4: 0.205 | I4: 0.33165829 | J4: 2.4615804e-05 | K4: 2.4615804e-05
A5: 2 | B5: I7, IV7, ii7, vi7 | C5: 3 | D5: 3–3 | E5: 2 | F5: – | G5: 0.38 | H5: 0.585 | I5: 0.33165829 | J5: 0.013293093 | K5: 0.013268478
A6: 3 | B6: iii7, vii°7 | C6: 5 | D6: 4–19 | E6: 7 | F6: F, E♭, A♭, G, D | G6: 0.06 | H6: 0.645 | I6: 0.86934673 | J6: 0.062596682 | K6: 0.049303589
A7: 4 | B7: vi, ii | C7: 2 | D7: 20–25 | E7: 7 | F7: – | G7: 0.01 | H7: 0.655 | I7: 0.86934673 | J7: 0.068650045 | K7: 0.0060533629
A8: 5 | B8: iii, vii° | C8: 4 | D8: 26–31 | E8: 7 | F8: – | G8: 0.005 | H8: 0.66 | I8: 0.86934673 | J8: 0.071854941 | K8: 0.0032048964
A9: 6 | B9: 9th: I, V, IV | C9: 12 | D9: 32–37 | E9: 7 | F9: – | G9: 0.01 | H9: 0.67 | I9: 0.86934673 | J9: 0.078639699 | K9: 0.0067847576
A10: 7 | B10: 9th: vi, ii, iii, vii° | C10: 13 | D10: 38–43 | E10: 7 | F10: – | G10: 0.007 | H10: 0.677 | I10: 0.86934673 | J10: 0.083699919 | K10: 0.0050602201
A11: 8 | B11: sus4: I, V, IV | C11: 6 | D11: 44–49 | E11: 7 | F11: – | G11: 0.005 | H11: 0.682 | I11: 0.86934673 | J11: 0.087478086 | K11: 0.0037781673
A12: 9 | B12: add9: I, V, IV | C12: 10 | D12: 50–64 | E12: 8 | F12: D♭ | G12: 0.005 | H12: 0.687 | I12: 0.91457286 | J12: 0.096152091 | K12: 0.0086740047
A13: 10 | B13: sus2: I, V, IV | C13: 8 | D13: 65–71 | E13: 8 | F13: – | G13: 0.003 | H13: 0.69 | I13: 0.91457286 | J13: 0.098699024 | K13: 0.0025469324
A14: 11 | B14: add9: vi, ii, iii, vii° | C14: 11 | D14: 72–78 | E14: 8 | F14: – | G14: 0.004 | H14: 0.694 | I14: 0.91457286 | J14: 0.10218217 | K14: 0.0034831495
A15: 12 | B15: sus4: vi, ii, iii, vii° | C15: 7 | D15: 79–97 | E15: 9 | F15: A | G15: 0.004 | H15: 0.698 | I15: 0.94974874 | J15: 0.10983513 | K15: 0.0076529557
... A20: 17 | B20: 13th: vi, ii, iii, vii° | C20: 17 | D20: 178–188 | E20: 12 | F20: – | G20: 0.001 | H20: 0.704 | I20: 1 | J20: 0.12174074 | K20: 0.0010338856

Sheet Pop Plan B
A1: Pop Plan B — key order: C, G, D, A, F, E, B♭, E♭, A♭, D♭, B, F♯
A3: Chunk | B3: Chords added (group) | C3: Original group # | D3: Levels | E3: Keys at chunk end | F3: Newly in this chunk: keys | G3: Chord use added | H3: Chord use, cumulative | I3: Key coverage, cumulative | J3: Songs playable, cumulative | K3: Songs added by this chunk
A4: 1 | B4: I, IV, V, V7 | C4: 1 | D4: 1–2 | E4: 2 | F4: C, G | G4: 0.62 | H4: 0.62 | I4: 0.26395939 | J4: 0.024182186 | K4: 0.024182186
A5: 2 | B5: vi, ii | C5: 2 | D5: 3–3 | E5: 2 | F5: – | G5: 0.19 | H5: 0.81 | I5: 0.26395939 | J5: 0.092036949 | K5: 0.067854762
A6: 3 | B6: bVII, bVI | C6: 14 | D6: 4–4 | E6: 2 | F6: – | G6: 0.06 | H6: 0.87 | I6: 0.26395939 | J6: 0.13156288 | K6: 0.039525934
A7: 4 | B7: iii, vii° | C7: 4 | D7: 5–5 | E7: 2 | F7: – | G7: 0.035 | H7: 0.905 | I7: 0.26395939 | J7: 0.16024335 | K7: 0.028680467
A8: 5 | B8: iv, bIII, II | C8: 15 | D8: 6–56 | E8: 12 | F8: D, A, F, E, B♭, E♭, A♭, D♭, B, F♯ | G8: 0.04 | H8: 0.945 | I8: 1 | J8: 0.7536315 | K8: 0.59338815
A9: 6 | B9: sus4: I, V, IV | C9: 6 | D9: 57–67 | E9: 12 | F9: – | G9: 0.007 | H9: 0.952 | I9: 1 | J9: 0.78196037 | K9: 0.028328867
A10: 7 | B10: add9: I, V, IV | C10: 10 | D10: 68–78 | E10: 12 | F10: – | G10: 0.006 | H10: 0.958 | I10: 1 | J10: 0.80691455 | K10: 0.024954181
A11: 8 | B11: sus2: I, V, IV | C11: 8 | D11: 79–89 | E11: 12 | F11: – | G11: 0.005 | H11: 0.963 | I11: 1 | J11: 0.82819277 | K11: 0.021278224
A12: 9 | B12: I7, IV7, ii7, vi7 | C12: 3 | D12: 90–100 | E12: 12 | F12: – | G12: 0.011 | H12: 0.974 | I12: 1 | J12: 0.87658651 | K12: 0.048393742
A13: 10 | B13: 9th: I, V, IV | C13: 12 | D13: 101–111 | E13: 12 | F13: – | G13: 0.003 | H13: 0.977 | I13: 1 | J13: 0.89016972 | K13: 0.01358321
A14: 11 | B14: sus4: vi, ii, iii, vii° | C14: 7 | D14: 112–122 | E14: 12 | F14: – | G14: 0.002 | H14: 0.979 | I14: 1 | J14: 0.89931836 | K14: 0.0091486356
A15: 12 | B15: sus2: vi, ii, iii, vii° | C15: 9 | D15: 123–133 | E15: 12 | F15: – | G15: 0.002 | H15: 0.981 | I15: 1 | J15: 0.90854206 | K15: 0.0092237008
... A18: 15 | B18: 9th: vi, ii, iii, vii° | C18: 13 | D18: 156–166 | E18: 12 | F18: – | G18: 0.001 | H18: 0.985 | I18: 1 | J18: 0.9272165 | K18: 0.0046971357

Sheet Jazz Plan B
A1: Jazz Plan B — key order: C, B♭, F, E♭, A♭, G, D, D♭, A, E, B, F♯
A3: Chunk | B3: Chords added (group) | C3: Original group # | D3: Levels | E3: Keys at chunk end | F3: Newly in this chunk: keys | G3: Chord use added | H3: Chord use, cumulative | I3: Key coverage, cumulative | J3: Songs playable, cumulative | K3: Songs added by this chunk
A4: 1 | B4: I, IV, V, V7 | C4: 1 | D4: 1–2 | E4: 2 | F4: C, B♭ | G4: 0.205 | H4: 0.205 | I4: 0.33165829 | J4: 2.4615804e-05 | K4: 2.4615804e-05
A5: 2 | B5: I7, IV7, ii7, vi7 | C5: 3 | D5: 3–3 | E5: 2 | F5: – | G5: 0.38 | H5: 0.585 | I5: 0.33165829 | J5: 0.013293093 | K5: 0.013268478
A6: 3 | B6: Secondary dominants (V7/ii, V7/V, ...) | C6: 18 | D6: 4–4 | E6: 2 | F6: – | G6: 0.1 | H6: 0.685 | I6: 0.33165829 | J6: 0.034263702 | K6: 0.020970609
A7: 4 | B7: iii7, vii°7 | C7: 5 | D7: 5–5 | E7: 2 | F7: – | G7: 0.06 | H7: 0.745 | I7: 0.33165829 | J7: 0.056705932 | K7: 0.02244223
A8: 5 | B8: Minor-key & chromatic: i7, iiø7, dim7, bII7 | C8: 19 | D8: 6–26 | E8: 6 | F8: F, E♭, A♭, G | G8: 0.08 | H8: 0.825 | I8: 0.81407035 | J8: 0.25667622 | K8: 0.19997028
A9: 6 | B9: vi, ii | C9: 2 | D9: 27–31 | E9: 6 | F9: – | G9: 0.01 | H9: 0.835 | I9: 0.81407035 | J9: 0.27591848 | K9: 0.019242265
A10: 7 | B10: iii, vii° | C10: 4 | D10: 32–36 | E10: 6 | F10: – | G10: 0.005 | H10: 0.84 | I10: 0.81407035 | J10: 0.28598131 | K10: 0.010062831
A11: 8 | B11: 9th: I, V, IV | C11: 12 | D11: 37–41 | E11: 6 | F11: – | G11: 0.01 | H11: 0.85 | I11: 0.81407035 | J11: 0.30702624 | K11: 0.021044927
A12: 9 | B12: 9th: vi, ii, iii, vii° | C12: 13 | D12: 42–55 | E12: 7 | F12: D | G12: 0.007 | H12: 0.857 | I12: 0.86934673 | J12: 0.34441175 | K12: 0.03738551
A13: 10 | B13: sus4: I, V, IV | C13: 6 | D13: 56–61 | E13: 7 | F13: – | G13: 0.005 | H13: 0.862 | I13: 0.86934673 | J13: 0.3566454 | K13: 0.012233647
A14: 11 | B14: add9: I, V, IV | C14: 10 | D14: 62–78 | E14: 8 | F14: D♭ | G14: 0.005 | H14: 0.867 | I14: 0.91457286 | J14: 0.38844801 | K14: 0.03180261
A15: 12 | B15: sus2: I, V, IV | C15: 8 | D15: 79–85 | E15: 8 | F15: – | G15: 0.003 | H15: 0.87 | I15: 0.91457286 | J15: 0.39658276 | K15: 0.0081347507
... A22: 19 | B22: 13th: vi, ii, iii, vii° | C22: 17 | D22: 200–210 | E22: 12 | F22: – | G22: 0.001 | H22: 0.884 | I22: 1 | J22: 0.47721445 | K22: 0.0032298658

Sheet Inputs
A1: Group (original #) | B1: Chords | C1: Pop % of chord use | D1: Jazz % of chord use
A2: 1 | B2: I, IV, V, V7 | C2: 0.62 | D2: 0.205
A3: 2 | B3: vi, ii | C3: 0.19 | D3: 0.01
A4: 3 | B4: I7, IV7, ii7, vi7 | C4: 0.011 | D4: 0.38
A5: 4 | B5: iii, vii° | C5: 0.035 | D5: 0.005
A6: 5 | B6: iii7, vii°7 | C6: 0.001 | D6: 0.06
A7: 6 | B7: sus4: I, V, IV | C7: 0.007 | D7: 0.005
A8: 7 | B8: sus4: vi, ii, iii, vii° | C8: 0.002 | D8: 0.004
A9: 8 | B9: sus2: I, V, IV | C9: 0.005 | D9: 0.003
A10: 9 | B10: sus2: vi, ii, iii, vii° | C10: 0.002 | D10: 0.002
A11: 10 | B11: add9: I, V, IV | C11: 0.006 | D11: 0.005
A12: 11 | B12: add9: vi, ii, iii, vii° | C12: 0.002 | D12: 0.004
A13: 12 | B13: 9th: I, V, IV | C13: 0.003 | D13: 0.01
... A18: 17 | B18: 13th: vi, ii, iii, vii° | C18: 0 | D18: 0.001
A19: Plan B groups
A20: B1 | B20: Pop: bVII, bVI | Jazz: secondary dominants (V7/ii, V7/V, ...) | C20: 0.06 | D20: 0.1
A21: B2 | B21: Pop: iv, bIII, II | Jazz: i7, iiø7, dim7, bII7 (minor-key & chromatic) | C21: 0.04 | D21: 0.08
A24: Key order (original) | B24: Key (major / relative minor) | C24: Pop % of music | D24: Jazz % of music
A25: 1 | B25: C / Am | C25: 0.135 | D25: 0.14
A26: 2 | B26: D / Bm | C26: 0.115 | D26: 0.055
A27: 3 | B27: G / Em | C27: 0.125 | D27: 0.08
A28: 4 | B28: A / F♯m | C28: 0.095 | D28: 0.035
A29: 5 | B29: F / Dm | C29: 0.09 | D29: 0.17
A30: 6 | B30: D♭ / B♭m | C30: 0.055 | D30: 0.045
A31: 7 | B31: B♭ / Gm | C31: 0.07 | D31: 0.19
A32: 8 | B32: E♭ / Cm | C32: 0.065 | D32: 0.14
A33: 9 | B33: E / C♯m | C33: 0.085 | D33: 0.02
A34: 10 | B34: A♭ / Fm | C34: 0.06 | D34: 0.09
A35: 11 | B35: B / G♯m | C35: 0.055 | D35: 0.015
A36: 12 | B36: F♯ / E♭m | C36: 0.035 | D36: 0.015
A38: Song-level exponent: Pop 5, Jazz 6 (songs playable = key coverage × chord-use coverage ^ exponent).
A40: These are the same rough shares as the chunk-coverage workbook. The Plan B shares are carved out of the "Not in the app" share (Pop 11.5% → 1.5%; Jazz 29.6% → 11.6%). Edit the blue cells and ask for a regenerate; the other sheets are computed by script and do not recalculate.
